Workbook

Sheet 动作事件
A1: 表1 动作事件（A1-A6）
A2: 逐通听录音，把每个可观测动作标出来。A4(沉默变长)只用于更新状态，不单独触发响应。「是否关键动作」填人工金标准，用来算触发覆盖率。
A4: 通话ID | B4: 动作时间戳(秒) | C4: 动作类型 | D4: 原文片段 | E4: 触发来源 | F4: 是否关键动作(人工金标准) | G4: 备注

Sheet 状态快照
A1: 表2 状态快照（每个动作后的状态）
A2: 建议只对 20 通通话完整落库，其余只落增量——这张表会很大。承诺与矛盾只增不减（单调性），旧信息不覆盖只记冲突。
A4: 通话ID | B4: 动作时间戳(秒) | C4: 阶段 | D4: 议题列表 | E4: 客户立场 | F4: 未决事项 | G4: 已说承诺 | H4: 检测到的矛盾 | I4: 上一个动作 | J4: 备注

Sheet 响应事件
A1: 表3 响应事件（R0-R5，含沉默）
A2: R0 沉默是默认响应，也必须落库——否则算不出沉默比。「是否假阳性」只对 R2 填。
A4: 通话ID | B4: 响应时间戳(秒) | C4: 响应类型 | D4: 输出内容 | E4: 依据 | F4: 置信度(1-5) | G4: 是否假阳性(R2专用) | H4: 是否被抑制 | I4: 备注

Sheet 人工核对
A1: 表4 人工核对（状态准确率，仅 20 通）
A2: 让另一个人独立建同一份状态表再对照。两人的一致率就是状态准确率的上限——如果两个人自己都对不上 80%，先改字段定义，不要写代码。
A4: 通话ID | B4: 动作时间戳(秒) | C4: 人工判定状态 | D4: 系统状态 | E4: 是否一致 | F4: 差异类型 | G4: 差异说明

Sheet 阈值
A1: 阈值与容量参数
A2: 全部是待校准的初始值。改这里，「统计」表的判定会跟着变。上线前必须替换成真实通话数据算出的数字。
A4: 参数 | B4: 值 | C4: 说明
A5: 沉默比下限 | B5: 0.7 | C5: 低于此值说明触发太宽，产品是噪音源
A6: 状态准确率下限 | B6: 0.8 | C6: 最致命的一条：状态不准，后面全建立在错误前提上
A7: 触发覆盖率下限 | B7: 0.5 | C7: 低于此值说明系统没在听
A8: 判死用覆盖率 | B8: 0.3 | C8: 低于此值直接判死
A9: 响应延迟P95上限(秒) | B9: 1.5 | C9: 过期响应比没有响应更糟
A10: 判死用延迟(秒) | B10: 3 | C10: 超过此值直接判死
A11: R2假阳性上限 | B11: 0.2 | C11: 阻断纠错错了最伤信任，它拿着最高优先级
A12: R1占比上限 | B12: 0.2 | C12: 超过说明系统在空转，状态没有实质推进
A13: 单通话响应上限(不含R0) | B13: 12 | C13: 超过说明触发太宽
A14: R2每通上限 | B14: 3 | C14: 超过说明判据太松
A15: 单组选项数上限 | B15: 4 | C15: 超过出现选择瘫痪
A16: 常驻显示响应数 | B16: 1 | C16: 视野边缘的注意力预算
A17: 刷新频率上限(次/30秒) | B17: 1 | C17: 画面抖动比误报更烦人

Sheet 统计
A1: v0.3 指标汇总（不依赖是否执行选项）
A2: 全部自动计算，数据来自「动作事件」「响应事件」「人工核对」。按 v0.3 要求，不统计「用户是否执行选项」——那部分遥测已从设计里移除。
A4: 指标 | B4: 计算 | C4: 值 | D4: 门槛 | E4: 判定
A5: 动作总数 | C5: =COUNTIF('动作事件'!$C$5:$C$304,"<>")-COUNTBLANK('动作事件'!$C$5:$C$304) -> 0
A6: 响应总数 | C6: =COUNTIF('响应事件'!$C$5:$C$304,"<>")-COUNTBLANK('响应事件'!$C$5:$C$304) -> 0
A7: R0 沉默数 | C7: =COUNTIF('响应事件'!$C$5:$C$304,"R0") -> 0
A8: 沉默比 | B8: R0/响应总数，应≥70% | C8: =IF($C$6=0,"",$C$7/$C$6) -> 0 | D8: =阈值!$B$5 -> 0 | E8: =IF($C$8="","未标注",IF($C$8<阈值!$B$5,"判死：太吵","通过")) -> 0
A9: 关键动作数 | C9: =COUNTIF('动作事件'!$F$5:$F$304,"是") -> 0
A10: 被识别的关键动作 | C10: =COUNTIFS('动作事件'!$F$5:$F$304,"是",'动作事件'!$C$5:$C$304,"<>") -> 0
A11: 触发覆盖率 | B11: 被识别的关键动作/关键动作数 | C11: =IF($C$9=0,"",$C$10/$C$9) -> 0 | D11: =阈值!$B$7 -> 0 | E11: =IF($C$11="","未标注",IF($C$11<阈值!$B$8,"判死：没在听",IF($C$11<阈值!$B$7,"警告：漏得多","通过"))) -> 0
A12: 一致数 | C12: =COUNTIF('人工核对'!$E$5:$E$304,"一致") -> 0
A13: 不一致数 | C13: =COUNTIF('人工核对'!$E$5:$E$304,"不一致") -> 0
A14: 状态准确率 | B14: 一致/(一致+不一致)，最致命指标 | C14: =IF(($C$12+$C$13)=0,"",$C$12/($C$12+$C$13)) -> 0 | D14: =阈值!$B$6 -> 0 | E14: =IF($C$14="","未标注",IF($C$14<阈值!$B$6,"判死：状态不准","通过")) -> 0
A17: 响应类型分布（R0 应占七成以上）
A18: 响应 | B18: 次数 | C18: 占比 | D18: 说明
A19: R0 | B19: =COUNTIF('响应事件'!$C$5:$C$304,$A19) -> 0 | C19: =IF($C$6=0,"",$B19/$C$6) -> 0 | D19: 默认状态。占比低说明触发太宽
A20: R1 | B20: =COUNTIF('响应事件'!$C$5:$C$304,$A20) -> 0 | C20: =IF($C$6=0,"",$B20/$C$6) -> 0 | D20: 纯记账，占比应低
A21: R2 | B21: =COUNTIF('响应事件'!$C$5:$C$304,$A21) -> 0 | C21: =IF($C$6=0,"",$B21/$C$6) -> 0 | D21: 最高优先级，错了最伤信任
A22: R3 | B22: =COUNTIF('响应事件'!$C$5:$C$304,$A22) -> 0 | C22: =IF($C$6=0,"",$B22/$C$6) -> 0 | D22: 决策点选项
A23: R4 | B23: =COUNTIF('响应事件'!$C$5:$C$304,$A23) -> 0 | C23: =IF($C$6=0,"",$B23/$C$6) -> 0 | D23: 前瞻提示
A24: R5 | B24: =COUNTIF('响应事件'!$C$5:$C$304,$A24) -> 0 | C24: =IF($C$6=0,"",$B24/$C$6) -> 0 | D24: 静默结转，不显示
A25: R1 占比判定 | B25: =IF($B19=0,"",IF($C19>阈值!$B$12,"判死：系统在空转","通过")) -> 0
A27: R2 阻断性纠错的假阳性
A28: 项目 | B28: 数值
A29: R2 总次数 | B29: =COUNTIF('响应事件'!$C$5:$C$304,"R2") -> 0
A30: 判定为假阳性 | B30: =COUNTIF('响应事件'!$G$5:$G$304,"是") -> 0
A31: R2 假阳性率 | B31: =IF($B29=0,"",$B30/$B29) -> 0
A32: 判定 | B32: =IF($B32=0,"未标注",IF($B31>阈值!$B$11,"判死：纠错不可信","通过")) -> 0
A35: 动作类型分布（用来砍掉识别不准的动作类型）
A36: 动作 | B36: 次数 | C36: 占比
A37: A1 | B37: =COUNTIFS('动作事件'!$C$5:$C$304,$A37&"*") -> 0 | C37: =IF($C$4=0,"",$B37/$C$4) -> 0
A38: A2 | B38: =COUNTIFS('动作事件'!$C$5:$C$304,$A38&"*") -> 0 | C38: =IF($C$4=0,"",$B38/$C$4) -> 0
A39: A3 | B39: =COUNTIFS('动作事件'!$C$5:$C$304,$A39&"*") -> 0 | C39: =IF($C$4=0,"",$B39/$C$4) -> 0
A40: A4 | B40: =COUNTIFS('动作事件'!$C$5:$C$304,$A40&"*") -> 0 | C40: =IF($C$4=0,"",$B40/$C$4) -> 0
A41: A5 | B41: =COUNTIFS('动作事件'!$C$5:$C$304,$A41&"*") -> 0 | C41: =IF($C$4=0,"",$B41/$C$4) -> 0
A42: A6 | B42: =COUNTIFS('动作事件'!$C$5:$C$304,$A42&"*") -> 0 | C42: =IF($C$4=0,"",$B42/$C$4) -> 0
A45: 状态差异类型（指导你改字段定义还是改代码）
A46: 差异类型 | B46: 次数
A47: 动作漏识别 | B47: =COUNTIF('人工核对'!$F$5:$F$304,$A47) -> 0
A48: 字段定义不清 | B48: =COUNTIF('人工核对'!$F$5:$F$304,$A48) -> 0
...
